An error occurred: Invalid number of arguments
Traceback (most recent call last):
  File "/home/jake/Documents/EEE/Cascade Circuit Solver/main.py", line 81, in <module>
    raise ValueError("Invalid number of arguments")
ValueError: Invalid number of arguments

During handling of the above exception, another exception occurred:

Traceback (most recent call last):
  File "/home/jake/Documents/EEE/Cascade Circuit Solver/main.py", line 91, in <module>
    write_empty_csv(output_file_path)
                    ^^^^^^^^^^^^^^^^
NameError: name 'output_file_path' is not defined
